<?xml version="1.0" ?>
<robot name="manipulator1_robot" xmlns:xacro="http://www.ros.org/wiki/xacro">

    <xacro:include filename="$(find manipulator1_robot_description)/urdf/gazebo.urdf.xacro"/>

    <link name="world"/>
    <link name="base_link">
        <visual>
            <origin xyz="0 0 0.05" rpy="0 0 0"/>
            <geometry>
                <cylinder radius="0.3" length="0.1"/>
            </geometry>
            <material name="dark_gray">
                <color rgba="0.3 0.3 0.3 1.0"/>
            </material>
        </visual>
        <collision>
            <origin xyz="0 0 0.05" rpy="0 0 0"/>
            <geometry>
                <cylinder radius="0.3" length="0.1"/>
            </geometry>
        </collision>
        <inertial>
            <origin xyz="0 0 0" rpy="0 0 0"/>
            <mass value="40.0"/>
            <inertia ixx="10.0" ixy="0.0" ixz="0.0" iyy="10.0" iyz="0.0" izz="10.0"/>
        </inertial>
    </link>

    <joint name="world_to_base_link" type="fixed">
        <parent link="world"/>
        <child link="base_link"/>
        <origin xyz="0 0 0" rpy="0 0 0"/>
    </joint>

    <link name="link1">
        <visual>
            <origin xyz="0 0 0.15" rpy="0 0 0"/>
            <geometry>
                <box size="0.10 0.10 0.3"/>
            </geometry>
            <material name="light_gray">
                <color rgba="0.8 0.8 0.8 1.0"/>
            </material>
        </visual>
        <collision>
            <origin xyz="0 0 0.15" rpy="0 0 0"/>
            <geometry>
                <box size="0.10 0.10 0.3"/>
            </geometry>
        </collision>
        <inertial>
            <origin xyz="0 0 0" rpy="0 0 0"/>
            <mass value="5.0"/>
            <inertia ixx="0.05" ixy="0.0" ixz="0.0" iyy="0.05" iyz="0.0" izz="0.05"/>
        </inertial>
    </link>

    <joint name="joint1" type="revolute">
        <parent link="base_link"/>
        <child link="link1"/>
        <origin xyz="0 0 0.1" rpy="0 0 0"/>
        <axis xyz="0 0 1"/>
        <limit effort="1000" velocity="1.0" lower="${-pi}" upper="${pi}"/>
    </joint>

    <transmission name="joint1_tran">
        <type>transmission_interface/SimpleTransmission</type>
        <joint name="joint1" >
            <hardwareInterface>hardware_interface/PositionJointInterface</hardwareInterface>
            <mechanicalReduction>1</mechanicalReduction>
        </joint>

        <actuator name="joint1_motor">
            <hardwareInterface>hardware_interface/PositionJointInterface</hardwareInterface>
            <mechanicalReduction>1</mechanicalReduction>
        </actuator>
    </transmission>

    <link name="link2">
        <visual>
            <origin xyz="0 0.05 0.20" rpy="0 0 0"/>
            <geometry>
                <box size="0.1 0.1 0.5"/>
            </geometry>
            <material name="gray">
                <color rgba="0.5 0.5 0.5 1.0"/>
            </material>
        </visual>
        <collision>
            <origin xyz="0 0.05 0.20" rpy="0 0 0"/>
            <geometry>
                <box size="0.1 0.1 0.5"/>
            </geometry>
        </collision>
        <inertial>
            <origin xyz="0 0 0" rpy="0 0 0"/>
            <mass value="3.0"/>
            <inertia ixx="0.03" ixy="0.0" ixz="0.0" iyy="0.03" iyz="0.0" izz="0.03"/>
        </inertial>
    </link>

    <joint name="joint2" type="revolute">
        <parent link="link1"/>
        <child link="link2"/>
        <origin xyz="0 0.05 0.25" rpy="0 0 0"/>
        <axis xyz="0 1 0"/>
        <limit effort="1000" velocity="1.0" lower="${-pi}" upper="${pi}"/>
    </joint>

    <transmission name="joint2_tran">
        <type>transmission_interface/SimpleTransmission</type>
        <joint name="joint2" >
            <hardwareInterface>hardware_interface/PositionJointInterface</hardwareInterface>
            <mechanicalReduction>1</mechanicalReduction>
        </joint>

        <actuator name="joint2_motor">
            <hardwareInterface>hardware_interface/PositionJointInterface</hardwareInterface>
            <mechanicalReduction>1</mechanicalReduction>
        </actuator>
    </transmission>

    <link name="link3">
        <visual>
            <origin xyz="0 -0.05 0.05" rpy="0 0 0"/>
            <geometry>
                <box size="0.1 0.1 0.2"/>
            </geometry>
            <material name="light_gray">
                <color rgba="0.8 0.8 0.8 1.0"/>
            </material>
        </visual>
        <collision>
            <origin xyz="0 -0.05 0.05" rpy="0 0 0"/>
            <geometry>
                <box size="0.1 0.1 0.2"/>
            </geometry>
        </collision>
        <inertial>
            <origin xyz="0 0 0" rpy="0 0 0"/>
            <mass value="1.0"/>
            <inertia ixx="0.01" ixy="0.0" ixz="0.0" iyy="0.01" iyz="0.0" izz="0.01"/>
        </inertial>
    </link>

    <joint name="joint3" type="revolute">
        <parent link="link2"/>
        <child link="link3"/>
        <origin xyz="0 0 0.4" rpy="0 0 0"/>
        <axis xyz="0 1 0"/>
        <limit effort="1000" velocity="1.0" lower="${-pi}" upper="${pi}"/>
    </joint>

    <transmission name="joint3_tran">
        <type>transmission_interface/SimpleTransmission</type>
        <joint name="joint3" >
            <hardwareInterface>hardware_interface/PositionJointInterface</hardwareInterface>
            <mechanicalReduction>1</mechanicalReduction>
        </joint>

        <actuator name="joint3_motor">
            <hardwareInterface>hardware_interface/PositionJointInterface</hardwareInterface>
            <mechanicalReduction>1</mechanicalReduction>
        </actuator>
    </transmission>

    <link name="link4">
        <visual>
            <origin xyz="0 0 0.05" rpy="0 0 0"/>
            <geometry>
                <box size="0.1 0.1 0.1"/>
            </geometry>
            <material name="gray"/>
        </visual>
        <collision>
            <origin xyz="0 0 0.05" rpy="0 0 0"/>
            <geometry>
                <box size="0.1 0.1 0.1"/>
            </geometry>
        </collision>
        <inertial>
            <origin xyz="0 0 0" rpy="0 0 0"/>
            <mass value="1.0"/>
            <inertia ixx="0.01" ixy="0.0" ixz="0.0" iyy="0.01" iyz="0.0" izz="0.01"/>
        </inertial>
    </link>

    <joint name="joint4" type="revolute">
        <parent link="link3"/>
        <child link="link4"/>
        <origin xyz="0 -0.05 0.15" rpy="0 0 0"/>
        <axis xyz="0 0 1"/>
        <limit effort="1000" velocity="1.0" lower="${-pi}" upper="${pi}"/>
    </joint>

    <transmission name="joint4_tran">
        <type>transmission_interface/SimpleTransmission</type>
        <joint name="joint4" >
            <hardwareInterface>hardware_interface/PositionJointInterface</hardwareInterface>
            <mechanicalReduction>1</mechanicalReduction>
        </joint>

        <actuator name="joint4_motor">
            <hardwareInterface>hardware_interface/PositionJointInterface</hardwareInterface>
            <mechanicalReduction>1</mechanicalReduction>
        </actuator>
    </transmission>

    <link name="link4_1">
        <visual>
            <origin xyz="0 0.025 0.15" rpy="0 0 0"/>
            <geometry>
                <box size="0.1 0.05 0.4"/>
            </geometry>
            <material name="gray"/>
        </visual>
        <collision>
            <origin xyz="0 0.025 0.15" rpy="0 0 0"/>
            <geometry>
                <box size="0.1 0.05 0.4"/>
            </geometry>
        </collision>
        <inertial>
            <origin xyz="0 0 0" rpy="0 0 0"/>
            <mass value="1.0"/>
            <inertia ixx="0.01" ixy="0.0" ixz="0.0" iyy="0.01" iyz="0.0" izz="0.01"/>
        </inertial>
    </link>

    <joint name="joint_link4" type="fixed">
        <parent link="link4"/>
        <child link="link4_1"/>
        <origin xyz="0 0.05 0.15" rpy="0 0 0"/>
    </joint>

    <link name="link5">
        <visual>
            <origin xyz="0 -0.05 0.03" rpy="0 0 0"/>
            <geometry>
                <box size="0.1 0.1 0.12"/>
            </geometry>
            <material name="light_gray"/>
        </visual>
        <collision>
            <origin xyz="0 -0.05 0.03" rpy="0 0 0"/>
            <geometry>
                <box size="0.1 0.1 0.12"/>
            </geometry>
        </collision>
        <inertial>
            <origin xyz="0 0 0" rpy="0 0 0"/>
            <mass value="1.0"/>
            <inertia ixx="0.01" ixy="0.0" ixz="0.0" iyy="0.01" iyz="0.0" izz="0.01"/>
        </inertial>
    </link>

    <joint name="joint5" type="revolute">
        <parent link="link4_1"/>
        <child link="link5"/>
        <origin xyz="0 0 0.3" rpy="0 0 0"/>
        <axis xyz="0 1 0"/>
        <limit effort="1000" velocity="1.0" lower="${-pi}" upper="${pi}"/>
    </joint>

    <transmission name="joint5_tran">
        <type>transmission_interface/SimpleTransmission</type>
        <joint name="joint5" >
            <hardwareInterface>hardware_interface/PositionJointInterface</hardwareInterface>
            <mechanicalReduction>1</mechanicalReduction>
        </joint>

        <actuator name="joint5_motor">
            <hardwareInterface>hardware_interface/PositionJointInterface</hardwareInterface>
            <mechanicalReduction>1</mechanicalReduction>
        </actuator>
    </transmission>

    <link name="link6">
        <visual>
            <origin xyz="0 0 0.03" rpy="0 0 0"/>
            <geometry>
                <cylinder radius="0.05" length="0.06"/>
            </geometry>
            <material name="light_gray"/>
        </visual>
        <collision>
            <origin xyz="0 0 0.03" rpy="0 0 0"/>
            <geometry>
                <cylinder radius="0.05" length="0.06"/>
            </geometry>
        </collision>
        <inertial>
            <origin xyz="0 0 0" rpy="0 0 0"/>
            <mass value="0.2"/>
            <inertia ixx="0.005" ixy="0.0" ixz="0.0" iyy="0.005" iyz="0.0" izz="0.005"/>
        </inertial>
    </link>

    <joint name="joint6" type="revolute">
        <parent link="link5"/>
        <child link="link6"/>
        <origin xyz="0 -0.05 0.08" rpy="0 0 0"/>
        <axis xyz="0 0 1"/>
        <limit effort="1000" velocity="1.0" lower="${-pi}" upper="${pi}"/>
    </joint>

    <transmission name="joint6_tran">
        <type>transmission_interface/SimpleTransmission</type>
        <joint name="joint6" >
            <hardwareInterface>hardware_interface/PositionJointInterface</hardwareInterface>
            <mechanicalReduction>1</mechanicalReduction>
        </joint>

        <actuator name="joint6_motor">
            <hardwareInterface>hardware_interface/PositionJointInterface</hardwareInterface>
            <mechanicalReduction>1</mechanicalReduction>
        </actuator>
    </transmission>
</robot>
